<?xml version="1.0" encoding="UTF-8"?>

<robot name="My RB1">
    <material name="blue">
        <color rgba="0 0 1 0.5"/>
    </material>

    <material name="white">
        <color rgba="1 1 1 1"/>
    </material>

    <material name="red">
        <color rgba="1 0 0 1"/>
    </material>


    <gazebo reference="base_link">
        <material>Gazebo/Black</material>
    </gazebo>


    <gazebo reference="front_caster">
        <preserveFixedJoint>true</preserveFixedJoint>
        <mu1>0</mu1>
        <mu2>0</mu2>
    </gazebo>


    <gazebo reference="back_caster">
        <preserveFixedJoint>true</preserveFixedJoint>
        <mu1>0</mu1>
        <mu2>0</mu2>
    </gazebo>


    <gazebo reference="right_wheel">
        <mu1>1</mu1>
        <mu2>1</mu2>
    </gazebo>


    <gazebo reference="left_wheel">
        <mu1>1</mu1>
        <mu2>1</mu2>
    </gazebo>


    <!-- Links -->
    <link name = "base_footprint">
    </link>

    <link name="base_link">
        <visual>
            <origin xyz="0 0 0" rpy="0 0 0"/>
            <geometry>
                <cylinder length="0.30" radius="0.25"/>
            </geometry>
            <material name="blue"/>
        </visual>
        <collision>
            <origin xyz="0 0 0" rpy="0 0 0"/>
            <geometry>
                <cylinder length="0.30" radius="0.25"/>
            </geometry>
        </collision>
        <inertial>
            <origin xyz="0 0 0" rpy="0 0 0"/>
            <mass value="25"/>
            <inertia ixx="1.5625" ixy="0" ixz="0" iyy="1.5625" iyz="0" izz="0.625"/>
        </inertial>
    </link>

    <link name="right_wheel">

        <inertial>
            <origin xyz="0 0 0" rpy="0 0 0"/>
            <mass value="1"/>
            <inertia ixx="0.0125" ixy="0" ixz="0" iyy="0.0125" iyz="0" izz="0.025"/>
        </inertial>
        <visual>
            <origin xyz="0 0 0" rpy="1.5708 0 0"/> 
            <geometry>
                <cylinder length="0.03" radius="0.025"/>
            </geometry>
            <material name="red"/>
        </visual>
        <collision>
            <origin xyz="0 0 0" rpy="1.5708 0 0"/> 
            <geometry>
                <cylinder length="0.03" radius="0.025"/>
            </geometry>
        </collision>
    </link>

    <link name="left_wheel">
        <inertial>
            <origin xyz="0 0 0" rpy="0 0 0"/>
            <mass value="1"/>
            <inertia ixx="0.0125" ixy="0" ixz="0" iyy="0.0125" iyz="0" izz="0.025"/>
        </inertial>
        <visual>
            <origin xyz="0 0 0" rpy="1.5708 0 0"/> 
            <geometry>
                <cylinder length="0.03" radius="0.025"/>
            </geometry>
            <material name="red"/>
        </visual>
        <collision>
            <origin xyz="0 0 0" rpy="1.5708 0 0"/> 
            <geometry>
                <cylinder length="0.03" radius="0.025"/>
            </geometry>
        </collision>

    </link>

    <link name="front_caster">
        <inertial>
            <origin xyz="0 0 0" rpy="0 0 0"/>
            <mass value="0.5"/>
            <inertia ixx="0.003125" ixy="0" ixz="0" iyy="0.003125" iyz="0" izz="0.00625"/>
        </inertial>
        <visual>
            <geometry>
                <sphere radius="0.025"/>
            </geometry>
            <material name="white"/>
        </visual>
        <collision>
            <geometry>
                <sphere radius="0.025"/>
            </geometry>
            <surface>
                <friction>
                    <ode mu="0" mu2="0"/>
                </friction>
            </surface>
        </collision>
    </link>

    <link name="back_caster">
        <inertial>
            <origin xyz="0 0 0" rpy="0 0 0"/>
            <mass value="0.5"/>
            <inertia ixx="0.003125" ixy="0" ixz="0" iyy="0.003125" iyz="0" izz="0.00625"/>
        </inertial>
        <visual>
            <geometry>
                <sphere radius="0.025"/>
            </geometry>
            <material name="white"/>
        </visual>
        <collision>
            <geometry>
                <sphere radius="0.025"/>
            </geometry>
            <surface>
                <friction>
                    <ode mu="0" mu2="0"/>
                </friction>
            </surface>
        </collision>
    </link>

    <link name="front_laser">
        <inertial>
            <origin xyz="0 0 0" rpy="0 0 0"/>
            <mass value="0.1"/>
            <inertia ixx="0.0001" ixy="0" ixz="0" iyy="0.0001" iyz="0" izz="0.0001"/>
        </inertial>
    </link>

    <!-- Joints -->
    <joint name="base_to_base_link" type="fixed">
        <parent link="base_footprint"/>
        <child link="base_link"/>
        <origin xyz="0 0 0.15" rpy="0 0 0"/>
    </joint>

    <joint name="base_link_to_right_wheel" type="continuous">
        <parent link="base_link"/>
        <child link="right_wheel"/>
        <origin xyz="0 -0.25 -0.15" rpy="0 0 0"/>
        <axis xyz="0 1 0"/>

    </joint>

    <joint name="base_link_to_left_wheel" type="continuous">
        <parent link="base_link"/>
        <child link="left_wheel"/>
        <origin xyz="0 0.25 -0.15" rpy="0 0 0"/>
        <axis xyz="0 1 0"/>
    </joint>


    <joint name="base_link_to_front_caster" type="fixed">
        <parent link="base_link"/>
        <child link="front_caster"/>
        <origin xyz="-0.1 0 -0.15" rpy="0 0 0"/>
    </joint>

    <joint name="base_link_to_back_caster" type="fixed">
        <parent link="base_link"/>
        <child link="back_caster"/>
        <origin xyz="0.1 0 -0.15" rpy="0 0 0"/>
    </joint>

    <joint name="base_link_to_front_laser" type="fixed">
        <parent link="base_link"/>
        <child link="front_laser"/>
        <origin xyz="0.25 0 0.075" rpy="3.14159 0 0"/>
    </joint>


    <gazebo>
        <plugin filename="libgazebo_ros_diff_drive.so" name="differential_drive_controller">
            <alwaysOn>true</alwaysOn>
            <updateRate>20</updateRate>
            <leftJoint>base_link_to_left_wheel</leftJoint>
            <rightJoint>base_link_to_right_wheel</rightJoint>
            <wheelSeparation>1.3</wheelSeparation>
            <wheelDiameter>0.05</wheelDiameter>
            <torque>10</torque>
            <commandTopic>cmd_vel</commandTopic>
            <odometryTopic>odom</odometryTopic>
            <odometryFrame>odom</odometryFrame>
            <robotBaseFrame>base_link</robotBaseFrame>
        </plugin>
    </gazebo>

    <gazebo reference="front_laser">
        <sensor type="ray" name="head_hokuyo_sensor">
            <pose>0 0 0 0 0 0</pose>
            <visualize>true</visualize>
            <update_rate>20</update_rate>
            <ray>
                <scan>
                    <horizontal>
                        <samples>720</samples>
                        <resolution>1</resolution>
                        <min_angle>-1.570796</min_angle>
                        <max_angle>1.570796</max_angle>
                    </horizontal>
                </scan>
                <range>
                    <min>0.20</min>
                    <max>10.0</max>
                    <resolution>0.01</resolution>
                </range>
                <noise>
                    <type>gaussian</type>
                    <mean>0.0</mean>
                    <stddev>0.01</stddev>
                </noise>
            </ray>
            <plugin name="gazebo_ros_head_hokuyo_controller" filename="libgazebo_ros_laser.so">
                <topicName>/scan</topicName>
                <frameName>front_laser</frameName>
            </plugin>
        </sensor>
    </gazebo>

</robot>